[2022-04-29 01:44:45,937] {processor.py:163} INFO - Started process (PID=636) to work on /home/airflow/.local/lib/python3.7/site-packages/airflow/example_dags/example_latest_only_with_trigger.py
[2022-04-29 01:44:45,955] {processor.py:642} INFO - Processing file /home/airflow/.local/lib/python3.7/site-packages/airflow/example_dags/example_latest_only_with_trigger.py for tasks to queue
[2022-04-29 01:44:45,961] {logging_mixin.py:109} INFO - [2022-04-29 01:44:45,961] {dagbag.py:500} INFO - Filling up the DagBag from /home/airflow/.local/lib/python3.7/site-packages/airflow/example_dags/example_latest_only_with_trigger.py
[2022-04-29 01:44:46,121] {processor.py:652} INFO - DAG(s) dict_keys(['latest_only_with_trigger']) retrieved from /home/airflow/.local/lib/python3.7/site-packages/airflow/example_dags/example_latest_only_with_trigger.py
[2022-04-29 01:44:53,758] {logging_mixin.py:109} INFO - [2022-04-29 01:44:53,757] {process_utils.py:237} INFO - Waiting up to 5 seconds for processes to exit...
[2022-04-29 01:44:53,778] {logging_mixin.py:109} INFO - [2022-04-29 01:44:53,765] {base.py:706} ERROR - Exception during reset or similar
Traceback (most recent call last):
  File "/home/airflow/.local/lib/python3.7/site-packages/airflow/utils/session.py", line 31, in create_session
    yield session
  File "/home/airflow/.local/lib/python3.7/site-packages/airflow/utils/session.py", line 70, in wrapper
    return func(*args, session=session, **kwargs)
  File "/home/airflow/.local/lib/python3.7/site-packages/airflow/models/dagbag.py", line 608, in sync_to_db
    for attempt in run_with_db_retries(logger=self.log):
  File "/home/airflow/.local/lib/python3.7/site-packages/tenacity/__init__.py", line 382, in __iter__
    do = self.iter(retry_state=retry_state)
  File "/home/airflow/.local/lib/python3.7/site-packages/tenacity/__init__.py", line 349, in iter
    return fut.result()
  File "/usr/local/lib/python3.7/concurrent/futures/_base.py", line 428, in result
    return self.__get_result()
  File "/usr/local/lib/python3.7/concurrent/futures/_base.py", line 384, in __get_result
    raise self._exception
  File "/home/airflow/.local/lib/python3.7/site-packages/airflow/models/dagbag.py", line 620, in sync_to_db
    serialize_errors.extend(_serialize_dag_capturing_errors(dag, session))
  File "/home/airflow/.local/lib/python3.7/site-packages/airflow/models/dagbag.py", line 597, in _serialize_dag_capturing_errors
    self._sync_perm_for_dag(dag, session=session)
  File "/home/airflow/.local/lib/python3.7/site-packages/airflow/utils/session.py", line 67, in wrapper
    return func(*args, **kwargs)
  File "/home/airflow/.local/lib/python3.7/site-packages/airflow/models/dagbag.py", line 653, in _sync_perm_for_dag
    from airflow.www.security import ApplessAirflowSecurityManager
  File "/home/airflow/.local/lib/python3.7/site-packages/airflow/www/security.py", line 36, in <module>
    from airflow.www.views import (
  File "/home/airflow/.local/lib/python3.7/site-packages/airflow/www/views.py", line 3393, in <module>
    class ConnectionFormWidget(FormWidget):
  File "/home/airflow/.local/lib/python3.7/site-packages/airflow/www/views.py", line 3396, in ConnectionFormWidget
    field_behaviours = json.dumps(ProvidersManager().field_behaviours)
  File "/home/airflow/.local/lib/python3.7/site-packages/airflow/providers_manager.py", line 808, in field_behaviours
    self.initialize_providers_hooks()
  File "/home/airflow/.local/lib/python3.7/site-packages/airflow/providers_manager.py", line 217, in wrapped_function
    func(*args, **kwargs)
  File "/home/airflow/.local/lib/python3.7/site-packages/airflow/providers_manager.py", line 298, in initialize_providers_hooks
    self.initialize_providers_list()
  File "/home/airflow/.local/lib/python3.7/site-packages/airflow/providers_manager.py", line 217, in wrapped_function
    func(*args, **kwargs)
  File "/home/airflow/.local/lib/python3.7/site-packages/airflow/providers_manager.py", line 280, in initialize_providers_list
    self._discover_all_providers_from_packages()
  File "/home/airflow/.local/lib/python3.7/site-packages/airflow/providers_manager.py", line 342, in _discover_all_providers_from_packages
    package_name = dist.metadata['name']
  File "/home/airflow/.local/lib/python3.7/site-packages/importlib_metadata/__init__.py", line 618, in metadata
    return _adapters.Message(email.message_from_string(text))
  File "/usr/local/lib/python3.7/email/__init__.py", line 38, in message_from_string
    return Parser(*args, **kws).parsestr(s)
  File "/usr/local/lib/python3.7/email/parser.py", line 67, in parsestr
    return self.parse(StringIO(text), headersonly=headersonly)
  File "/usr/local/lib/python3.7/email/parser.py", line 56, in parse
    feedparser.feed(data)
  File "/usr/local/lib/python3.7/email/feedparser.py", line 175, in feed
    self._input.push(data)
  File "/usr/local/lib/python3.7/email/feedparser.py", line 120, in push
    self.pushlines(parts)
  File "/home/airflow/.local/lib/python3.7/site-packages/airflow/dag_processing/manager.py", line 499, in _exit_gracefully
    self.log.debug("Current Stacktrace is: %s", '\n'.join(map(str, inspect.stack())))
  File "/usr/local/lib/python3.7/inspect.py", line 1513, in stack
    return getouterframes(sys._getframe(1), context)
  File "/usr/local/lib/python3.7/inspect.py", line 1490, in getouterframes
    frameinfo = (frame,) + getframeinfo(frame, context)
  File "/usr/local/lib/python3.7/inspect.py", line 1464, in getframeinfo
    lines, lnum = findsource(frame)
  File "/usr/local/lib/python3.7/inspect.py", line 780, in findsource
    module = getmodule(object, file)
  File "/usr/local/lib/python3.7/inspect.py", line 742, in getmodule
    os.path.realpath(f)] = module.__name__
  File "/usr/local/lib/python3.7/posixpath.py", line 395, in realpath
    path, ok = _joinrealpath(filename[:0], filename, {})
  File "/usr/local/lib/python3.7/posixpath.py", line 429, in _joinrealpath
    if not islink(newpath):
  File "/usr/local/lib/python3.7/posixpath.py", line 171, in islink
    st = os.lstat(path)
  File "/home/airflow/.local/lib/python3.7/site-packages/airflow/dag_processing/manager.py", line 499, in _exit_gracefully
    self.log.debug("Current Stacktrace is: %s", '\n'.join(map(str, inspect.stack())))
  File "/usr/local/lib/python3.7/inspect.py", line 1513, in stack
    return getouterframes(sys._getframe(1), context)
  File "/usr/local/lib/python3.7/inspect.py", line 1490, in getouterframes
    frameinfo = (frame,) + getframeinfo(frame, context)
  File "/usr/local/lib/python3.7/inspect.py", line 1464, in getframeinfo
    lines, lnum = findsource(frame)
  File "/usr/local/lib/python3.7/inspect.py", line 780, in findsource
    module = getmodule(object, file)
  File "/usr/local/lib/python3.7/inspect.py", line 742, in getmodule
    os.path.realpath(f)] = module.__name__
  File "/usr/local/lib/python3.7/posixpath.py", line 395, in realpath
    path, ok = _joinrealpath(filename[:0], filename, {})
  File "/usr/local/lib/python3.7/posixpath.py", line 429, in _joinrealpath
    if not islink(newpath):
  File "/usr/local/lib/python3.7/posixpath.py", line 171, in islink
    st = os.lstat(path)
  File "/home/airflow/.local/lib/python3.7/site-packages/airflow/dag_processing/manager.py", line 503, in _exit_gracefully
    sys.exit(os.EX_OK)
SystemExit: 0

During handling of the above exception, another exception occurred:

Traceback (most recent call last):
  File "/home/airflow/.local/lib/python3.7/site-packages/sqlalchemy/engine/base.py", line 749, in _rollback_impl
    self.engine.dialect.do_rollback(self.connection)
  File "/home/airflow/.local/lib/python3.7/site-packages/sqlalchemy/dialects/mysql/base.py", line 2513, in do_rollback
    dbapi_connection.rollback()
MySQLdb._exceptions.OperationalError: (2013, 'Lost connection to MySQL server during query')

The above exception was the direct cause of the following exception:

Traceback (most recent call last):
  File "/home/airflow/.local/lib/python3.7/site-packages/sqlalchemy/pool/base.py", line 697, in _finalize_fairy
    fairy._reset(pool)
  File "/home/airflow/.local/lib/python3.7/site-packages/sqlalchemy/pool/base.py", line 891, in _reset
    self._reset_agent.rollback()
  File "/home/airflow/.local/lib/python3.7/site-packages/sqlalchemy/engine/base.py", line 1751, in rollback
    self._do_rollback()
  File "/home/airflow/.local/lib/python3.7/site-packages/sqlalchemy/engine/base.py", line 1789, in _do_rollback
    self.connection._rollback_impl()
  File "/home/airflow/.local/lib/python3.7/site-packages/sqlalchemy/engine/base.py", line 751, in _rollback_impl
    self._handle_dbapi_exception(e, None, None, None, None)
  File "/home/airflow/.local/lib/python3.7/site-packages/sqlalchemy/engine/base.py", line 1511, in _handle_dbapi_exception
    sqlalchemy_exception, with_traceback=exc_info[2], from_=e
  File "/home/airflow/.local/lib/python3.7/site-packages/sqlalchemy/util/compat.py", line 182, in raise_
    raise exception
  File "/home/airflow/.local/lib/python3.7/site-packages/sqlalchemy/engine/base.py", line 749, in _rollback_impl
    self.engine.dialect.do_rollback(self.connection)
  File "/home/airflow/.local/lib/python3.7/site-packages/sqlalchemy/dialects/mysql/base.py", line 2513, in do_rollback
    dbapi_connection.rollback()
sqlalchemy.exc.OperationalError: (MySQLdb._exceptions.OperationalError) (2013, 'Lost connection to MySQL server during query')
(Background on this error at: http://sqlalche.me/e/13/e3q8)
[2022-04-29 01:56:29,033] {processor.py:163} INFO - Started process (PID=324) to work on /home/airflow/.local/lib/python3.7/site-packages/airflow/example_dags/example_latest_only_with_trigger.py
[2022-04-29 01:56:29,038] {processor.py:642} INFO - Processing file /home/airflow/.local/lib/python3.7/site-packages/airflow/example_dags/example_latest_only_with_trigger.py for tasks to queue
[2022-04-29 01:56:29,042] {logging_mixin.py:109} INFO - [2022-04-29 01:56:29,041] {dagbag.py:500} INFO - Filling up the DagBag from /home/airflow/.local/lib/python3.7/site-packages/airflow/example_dags/example_latest_only_with_trigger.py
[2022-04-29 01:56:29,169] {processor.py:652} INFO - DAG(s) dict_keys(['latest_only_with_trigger']) retrieved from /home/airflow/.local/lib/python3.7/site-packages/airflow/example_dags/example_latest_only_with_trigger.py
[2022-04-29 01:57:10,246] {logging_mixin.py:109} INFO - [2022-04-29 01:57:10,245] {manager.py:496} INFO - Created Permission View: can edit on DAG:latest_only_with_trigger
[2022-04-29 01:57:10,278] {logging_mixin.py:109} INFO - [2022-04-29 01:57:10,277] {manager.py:496} INFO - Created Permission View: can read on DAG:latest_only_with_trigger
[2022-04-29 01:57:10,281] {logging_mixin.py:109} INFO - [2022-04-29 01:57:10,279] {dag.py:2398} INFO - Sync 1 DAGs
[2022-04-29 01:57:10,314] {logging_mixin.py:109} INFO - [2022-04-29 01:57:10,312] {dag.py:2417} INFO - Creating ORM DAG for latest_only_with_trigger
[2022-04-29 01:57:10,347] {logging_mixin.py:109} INFO - [2022-04-29 01:57:10,347] {dag.py:2937} INFO - Setting next_dagrun for latest_only_with_trigger to 2022-04-28T21:57:10.345512+00:00
[2022-04-29 01:57:10,390] {processor.py:171} INFO - Processing /home/airflow/.local/lib/python3.7/site-packages/airflow/example_dags/example_latest_only_with_trigger.py took 41.367 seconds
