[2022-04-29 01:57:10,436] {processor.py:163} INFO - Started process (PID=371) to work on /home/airflow/.local/lib/python3.7/site-packages/airflow/example_dags/example_branch_operator.py
[2022-04-29 01:57:10,448] {processor.py:642} INFO - Processing file /home/airflow/.local/lib/python3.7/site-packages/airflow/example_dags/example_branch_operator.py for tasks to queue
[2022-04-29 01:57:10,454] {logging_mixin.py:109} INFO - [2022-04-29 01:57:10,454] {dagbag.py:500} INFO - Filling up the DagBag from /home/airflow/.local/lib/python3.7/site-packages/airflow/example_dags/example_branch_operator.py
[2022-04-29 01:57:10,637] {processor.py:652} INFO - DAG(s) dict_keys(['example_branch_operator']) retrieved from /home/airflow/.local/lib/python3.7/site-packages/airflow/example_dags/example_branch_operator.py
[2022-04-29 01:57:17,822] {logging_mixin.py:109} INFO - [2022-04-29 01:57:17,821] {process_utils.py:237} INFO - Waiting up to 5 seconds for processes to exit...
[2022-04-29 01:57:17,841] {logging_mixin.py:109} INFO - [2022-04-29 01:57:17,828] {base.py:706} ERROR - Exception during reset or similar
Traceback (most recent call last):
  File "/usr/local/lib/python3.7/functools.py", line 54, in update_wrapper
    value = getattr(wrapped, attr)
AttributeError: 'builtin_function_or_method' object has no attribute '__annotations__'

During handling of the above exception, another exception occurred:

Traceback (most recent call last):
  File "/home/airflow/.local/lib/python3.7/site-packages/airflow/utils/session.py", line 31, in create_session
    yield session
  File "/home/airflow/.local/lib/python3.7/site-packages/airflow/utils/session.py", line 70, in wrapper
    return func(*args, session=session, **kwargs)
  File "/home/airflow/.local/lib/python3.7/site-packages/airflow/models/dagbag.py", line 608, in sync_to_db
    for attempt in run_with_db_retries(logger=self.log):
  File "/home/airflow/.local/lib/python3.7/site-packages/tenacity/__init__.py", line 382, in __iter__
    do = self.iter(retry_state=retry_state)
  File "/home/airflow/.local/lib/python3.7/site-packages/tenacity/__init__.py", line 349, in iter
    return fut.result()
  File "/usr/local/lib/python3.7/concurrent/futures/_base.py", line 428, in result
    return self.__get_result()
  File "/usr/local/lib/python3.7/concurrent/futures/_base.py", line 384, in __get_result
    raise self._exception
  File "/home/airflow/.local/lib/python3.7/site-packages/airflow/models/dagbag.py", line 620, in sync_to_db
    serialize_errors.extend(_serialize_dag_capturing_errors(dag, session))
  File "/home/airflow/.local/lib/python3.7/site-packages/airflow/models/dagbag.py", line 597, in _serialize_dag_capturing_errors
    self._sync_perm_for_dag(dag, session=session)
  File "/home/airflow/.local/lib/python3.7/site-packages/airflow/utils/session.py", line 67, in wrapper
    return func(*args, **kwargs)
  File "/home/airflow/.local/lib/python3.7/site-packages/airflow/models/dagbag.py", line 653, in _sync_perm_for_dag
    from airflow.www.security import ApplessAirflowSecurityManager
  File "/home/airflow/.local/lib/python3.7/site-packages/airflow/www/security.py", line 35, in <module>
    from airflow.www.utils import CustomSQLAInterface
  File "/home/airflow/.local/lib/python3.7/site-packages/airflow/www/utils.py", line 38, in <module>
    from airflow.utils.json import AirflowJsonEncoder
  File "/home/airflow/.local/lib/python3.7/site-packages/airflow/utils/json.py", line 25, in <module>
    import numpy as np
  File "/home/airflow/.local/lib/python3.7/site-packages/numpy/__init__.py", line 150, in <module>
    from . import core
  File "/home/airflow/.local/lib/python3.7/site-packages/numpy/core/__init__.py", line 22, in <module>
    from . import multiarray
  File "/home/airflow/.local/lib/python3.7/site-packages/numpy/core/multiarray.py", line 1627, in <module>
    def datetime_as_string(arr, unit=None, timezone=None, casting=None):
  File "/home/airflow/.local/lib/python3.7/site-packages/numpy/core/overrides.py", line 226, in decorator
    docs_from_dispatcher=docs_from_dispatcher)(implementation)
  File "/home/airflow/.local/lib/python3.7/site-packages/numpy/core/overrides.py", line 205, in decorator
    exec(source_object, scope)
  File "<__array_function__ internals>", line 2, in <module>
  File "/usr/local/lib/python3.7/functools.py", line 54, in update_wrapper
    value = getattr(wrapped, attr)
  File "/home/airflow/.local/lib/python3.7/site-packages/airflow/dag_processing/manager.py", line 499, in _exit_gracefully
    self.log.debug("Current Stacktrace is: %s", '\n'.join(map(str, inspect.stack())))
  File "/usr/local/lib/python3.7/inspect.py", line 1513, in stack
    return getouterframes(sys._getframe(1), context)
  File "/usr/local/lib/python3.7/inspect.py", line 1490, in getouterframes
    frameinfo = (frame,) + getframeinfo(frame, context)
  File "/usr/local/lib/python3.7/inspect.py", line 1464, in getframeinfo
    lines, lnum = findsource(frame)
  File "/usr/local/lib/python3.7/inspect.py", line 780, in findsource
    module = getmodule(object, file)
  File "/usr/local/lib/python3.7/inspect.py", line 742, in getmodule
    os.path.realpath(f)] = module.__name__
  File "/usr/local/lib/python3.7/posixpath.py", line 395, in realpath
    path, ok = _joinrealpath(filename[:0], filename, {})
  File "/usr/local/lib/python3.7/posixpath.py", line 429, in _joinrealpath
    if not islink(newpath):
  File "/usr/local/lib/python3.7/posixpath.py", line 171, in islink
    st = os.lstat(path)
  File "/home/airflow/.local/lib/python3.7/site-packages/airflow/dag_processing/manager.py", line 499, in _exit_gracefully
    self.log.debug("Current Stacktrace is: %s", '\n'.join(map(str, inspect.stack())))
  File "/usr/local/lib/python3.7/inspect.py", line 1513, in stack
    return getouterframes(sys._getframe(1), context)
  File "/usr/local/lib/python3.7/inspect.py", line 1490, in getouterframes
    frameinfo = (frame,) + getframeinfo(frame, context)
  File "/usr/local/lib/python3.7/inspect.py", line 1460, in getframeinfo
    filename = getsourcefile(frame) or getfile(frame)
  File "/usr/local/lib/python3.7/inspect.py", line 693, in getsourcefile
    if os.path.exists(filename):
  File "/usr/local/lib/python3.7/genericpath.py", line 19, in exists
    os.stat(path)
  File "/home/airflow/.local/lib/python3.7/site-packages/airflow/dag_processing/manager.py", line 503, in _exit_gracefully
    sys.exit(os.EX_OK)
SystemExit: 0

During handling of the above exception, another exception occurred:

Traceback (most recent call last):
  File "/home/airflow/.local/lib/python3.7/site-packages/sqlalchemy/engine/base.py", line 749, in _rollback_impl
    self.engine.dialect.do_rollback(self.connection)
  File "/home/airflow/.local/lib/python3.7/site-packages/sqlalchemy/dialects/mysql/base.py", line 2513, in do_rollback
    dbapi_connection.rollback()
MySQLdb._exceptions.OperationalError: (2013, 'Lost connection to MySQL server during query')

The above exception was the direct cause of the following exception:

Traceback (most recent call last):
  File "/home/airflow/.local/lib/python3.7/site-packages/sqlalchemy/pool/base.py", line 697, in _finalize_fairy
    fairy._reset(pool)
  File "/home/airflow/.local/lib/python3.7/site-packages/sqlalchemy/pool/base.py", line 891, in _reset
    self._reset_agent.rollback()
  File "/home/airflow/.local/lib/python3.7/site-packages/sqlalchemy/engine/base.py", line 1751, in rollback
    self._do_rollback()
  File "/home/airflow/.local/lib/python3.7/site-packages/sqlalchemy/engine/base.py", line 1789, in _do_rollback
    self.connection._rollback_impl()
  File "/home/airflow/.local/lib/python3.7/site-packages/sqlalchemy/engine/base.py", line 751, in _rollback_impl
    self._handle_dbapi_exception(e, None, None, None, None)
  File "/home/airflow/.local/lib/python3.7/site-packages/sqlalchemy/engine/base.py", line 1511, in _handle_dbapi_exception
    sqlalchemy_exception, with_traceback=exc_info[2], from_=e
  File "/home/airflow/.local/lib/python3.7/site-packages/sqlalchemy/util/compat.py", line 182, in raise_
    raise exception
  File "/home/airflow/.local/lib/python3.7/site-packages/sqlalchemy/engine/base.py", line 749, in _rollback_impl
    self.engine.dialect.do_rollback(self.connection)
  File "/home/airflow/.local/lib/python3.7/site-packages/sqlalchemy/dialects/mysql/base.py", line 2513, in do_rollback
    dbapi_connection.rollback()
sqlalchemy.exc.OperationalError: (MySQLdb._exceptions.OperationalError) (2013, 'Lost connection to MySQL server during query')
(Background on this error at: http://sqlalche.me/e/13/e3q8)
