[2022-04-29 01:44:48,214] {processor.py:163} INFO - Started process (PID=638) to work on /home/airflow/.local/lib/python3.7/site-packages/airflow/example_dags/example_skip_dag.py
[2022-04-29 01:44:48,222] {processor.py:642} INFO - Processing file /home/airflow/.local/lib/python3.7/site-packages/airflow/example_dags/example_skip_dag.py for tasks to queue
[2022-04-29 01:44:48,252] {logging_mixin.py:109} INFO - [2022-04-29 01:44:48,239] {dagbag.py:500} INFO - Filling up the DagBag from /home/airflow/.local/lib/python3.7/site-packages/airflow/example_dags/example_skip_dag.py
[2022-04-29 01:44:48,310] {processor.py:652} INFO - DAG(s) dict_keys(['example_skip_dag']) retrieved from /home/airflow/.local/lib/python3.7/site-packages/airflow/example_dags/example_skip_dag.py
[2022-04-29 01:44:53,838] {logging_mixin.py:109} INFO - [2022-04-29 01:44:53,838] {process_utils.py:237} INFO - Waiting up to 5 seconds for processes to exit...
[2022-04-29 01:44:53,855] {logging_mixin.py:109} INFO - [2022-04-29 01:44:53,844] {base.py:706} ERROR - Exception during reset or similar
Traceback (most recent call last):
  File "/home/airflow/.local/lib/python3.7/site-packages/psutil/_common.py", line 441, in wrapper
    ret = self._cache[fun]
AttributeError: _cache

During handling of the above exception, another exception occurred:

Traceback (most recent call last):
  File "/home/airflow/.local/lib/python3.7/site-packages/airflow/utils/session.py", line 31, in create_session
    yield session
  File "/home/airflow/.local/lib/python3.7/site-packages/airflow/utils/session.py", line 70, in wrapper
    return func(*args, session=session, **kwargs)
  File "/home/airflow/.local/lib/python3.7/site-packages/airflow/models/dagbag.py", line 608, in sync_to_db
    for attempt in run_with_db_retries(logger=self.log):
  File "/home/airflow/.local/lib/python3.7/site-packages/tenacity/__init__.py", line 382, in __iter__
    do = self.iter(retry_state=retry_state)
  File "/home/airflow/.local/lib/python3.7/site-packages/tenacity/__init__.py", line 349, in iter
    return fut.result()
  File "/usr/local/lib/python3.7/concurrent/futures/_base.py", line 428, in result
    return self.__get_result()
  File "/usr/local/lib/python3.7/concurrent/futures/_base.py", line 384, in __get_result
    raise self._exception
  File "/home/airflow/.local/lib/python3.7/site-packages/airflow/models/dagbag.py", line 620, in sync_to_db
    serialize_errors.extend(_serialize_dag_capturing_errors(dag, session))
  File "/home/airflow/.local/lib/python3.7/site-packages/airflow/models/dagbag.py", line 597, in _serialize_dag_capturing_errors
    self._sync_perm_for_dag(dag, session=session)
  File "/home/airflow/.local/lib/python3.7/site-packages/airflow/utils/session.py", line 67, in wrapper
    return func(*args, **kwargs)
  File "/home/airflow/.local/lib/python3.7/site-packages/airflow/models/dagbag.py", line 651, in _sync_perm_for_dag
    if dag.access_control or needs_perm_views(dag.dag_id):
  File "/home/airflow/.local/lib/python3.7/site-packages/airflow/models/dagbag.py", line 641, in needs_perm_views
    session.query(sqla_models.PermissionView)
  File "/home/airflow/.local/lib/python3.7/site-packages/sqlalchemy/orm/session.py", line 1589, in query
    return self._query_cls(entities, self, **kwargs)
  File "/home/airflow/.local/lib/python3.7/site-packages/sqlalchemy/orm/query.py", line 197, in __init__
    self._set_entities(entities)
  File "/home/airflow/.local/lib/python3.7/site-packages/sqlalchemy/orm/query.py", line 225, in _set_entities
    self._set_entity_selectables(self._entities)
  File "/home/airflow/.local/lib/python3.7/site-packages/sqlalchemy/orm/query.py", line 256, in _set_entity_selectables
    ent.setup_entity(*d[entity])
  File "/home/airflow/.local/lib/python3.7/site-packages/sqlalchemy/orm/query.py", line 4324, in setup_entity
    self._with_polymorphic = ext_info.with_polymorphic_mappers
  File "/home/airflow/.local/lib/python3.7/site-packages/sqlalchemy/util/langhelpers.py", line 893, in __get__
    obj.__dict__[self.__name__] = result = self.fget(obj)
  File "/home/airflow/.local/lib/python3.7/site-packages/sqlalchemy/orm/mapper.py", line 2155, in _with_polymorphic_mappers
    configure_mappers()
  File "/home/airflow/.local/lib/python3.7/site-packages/sqlalchemy/orm/mapper.py", line 3299, in configure_mappers
    mapper._post_configure_properties()
  File "/home/airflow/.local/lib/python3.7/site-packages/sqlalchemy/orm/mapper.py", line 1965, in _post_configure_properties
    prop.init()
  File "/home/airflow/.local/lib/python3.7/site-packages/sqlalchemy/orm/interfaces.py", line 197, in init
    self.do_init()
  File "/home/airflow/.local/lib/python3.7/site-packages/sqlalchemy/orm/relationships.py", line 2081, in do_init
    self._generate_backref()
  File "/home/airflow/.local/lib/python3.7/site-packages/sqlalchemy/orm/relationships.py", line 2385, in _generate_backref
    mapper._configure_property(backref_key, relationship)
  File "/home/airflow/.local/lib/python3.7/site-packages/sqlalchemy/orm/mapper.py", line 1852, in _configure_property
    prop.instrument_class(self)
  File "/home/airflow/.local/lib/python3.7/site-packages/sqlalchemy/orm/relationships.py", line 1081, in instrument_class
    doc=self.doc,
  File "/home/airflow/.local/lib/python3.7/site-packages/sqlalchemy/orm/attributes.py", line 1892, in register_descriptor
    class_, key, comparator=comparator, parententity=parententity
  File "/home/airflow/.local/lib/python3.7/site-packages/airflow/dag_processing/manager.py", line 501, in _exit_gracefully
    self.end()
  File "/home/airflow/.local/lib/python3.7/site-packages/airflow/dag_processing/manager.py", line 1182, in end
    kill_child_processes_by_pids(pids_to_kill)
  File "/home/airflow/.local/lib/python3.7/site-packages/airflow/utils/process_utils.py", line 224, in kill_child_processes_by_pids
    this_process = psutil.Process(os.getpid())
  File "/home/airflow/.local/lib/python3.7/site-packages/psutil/__init__.py", line 332, in __init__
    self._init(pid)
  File "/home/airflow/.local/lib/python3.7/site-packages/psutil/__init__.py", line 361, in _init
    self.create_time()
  File "/home/airflow/.local/lib/python3.7/site-packages/psutil/__init__.py", line 717, in create_time
    self._create_time = self._proc.create_time()
  File "/home/airflow/.local/lib/python3.7/site-packages/psutil/_pslinux.py", line 1661, in wrapper
    return fun(self, *args, **kwargs)
  File "/home/airflow/.local/lib/python3.7/site-packages/psutil/_pslinux.py", line 1873, in create_time
    ctime = float(self._parse_stat_file()['create_time'])
  File "/home/airflow/.local/lib/python3.7/site-packages/psutil/_pslinux.py", line 1661, in wrapper
    return fun(self, *args, **kwargs)
  File "/home/airflow/.local/lib/python3.7/site-packages/psutil/_common.py", line 444, in wrapper
    return fun(self)
  File "/home/airflow/.local/lib/python3.7/site-packages/psutil/_pslinux.py", line 1703, in _parse_stat_file
    with open_binary("%s/%s/stat" % (self._procfs_path, self.pid)) as f:
  File "/home/airflow/.local/lib/python3.7/site-packages/airflow/dag_processing/manager.py", line 503, in _exit_gracefully
    sys.exit(os.EX_OK)
SystemExit: 0

During handling of the above exception, another exception occurred:

Traceback (most recent call last):
  File "/home/airflow/.local/lib/python3.7/site-packages/sqlalchemy/engine/base.py", line 749, in _rollback_impl
    self.engine.dialect.do_rollback(self.connection)
  File "/home/airflow/.local/lib/python3.7/site-packages/sqlalchemy/dialects/mysql/base.py", line 2513, in do_rollback
    dbapi_connection.rollback()
MySQLdb._exceptions.OperationalError: (2013, 'Lost connection to MySQL server during query')

The above exception was the direct cause of the following exception:

Traceback (most recent call last):
  File "/home/airflow/.local/lib/python3.7/site-packages/sqlalchemy/pool/base.py", line 697, in _finalize_fairy
    fairy._reset(pool)
  File "/home/airflow/.local/lib/python3.7/site-packages/sqlalchemy/pool/base.py", line 891, in _reset
    self._reset_agent.rollback()
  File "/home/airflow/.local/lib/python3.7/site-packages/sqlalchemy/engine/base.py", line 1751, in rollback
    self._do_rollback()
  File "/home/airflow/.local/lib/python3.7/site-packages/sqlalchemy/engine/base.py", line 1789, in _do_rollback
    self.connection._rollback_impl()
  File "/home/airflow/.local/lib/python3.7/site-packages/sqlalchemy/engine/base.py", line 751, in _rollback_impl
    self._handle_dbapi_exception(e, None, None, None, None)
  File "/home/airflow/.local/lib/python3.7/site-packages/sqlalchemy/engine/base.py", line 1511, in _handle_dbapi_exception
    sqlalchemy_exception, with_traceback=exc_info[2], from_=e
  File "/home/airflow/.local/lib/python3.7/site-packages/sqlalchemy/util/compat.py", line 182, in raise_
    raise exception
  File "/home/airflow/.local/lib/python3.7/site-packages/sqlalchemy/engine/base.py", line 749, in _rollback_impl
    self.engine.dialect.do_rollback(self.connection)
  File "/home/airflow/.local/lib/python3.7/site-packages/sqlalchemy/dialects/mysql/base.py", line 2513, in do_rollback
    dbapi_connection.rollback()
sqlalchemy.exc.OperationalError: (MySQLdb._exceptions.OperationalError) (2013, 'Lost connection to MySQL server during query')
(Background on this error at: http://sqlalche.me/e/13/e3q8)
[2022-04-29 01:56:29,580] {processor.py:163} INFO - Started process (PID=326) to work on /home/airflow/.local/lib/python3.7/site-packages/airflow/example_dags/example_skip_dag.py
[2022-04-29 01:56:29,585] {processor.py:642} INFO - Processing file /home/airflow/.local/lib/python3.7/site-packages/airflow/example_dags/example_skip_dag.py for tasks to queue
[2022-04-29 01:56:29,594] {logging_mixin.py:109} INFO - [2022-04-29 01:56:29,594] {dagbag.py:500} INFO - Filling up the DagBag from /home/airflow/.local/lib/python3.7/site-packages/airflow/example_dags/example_skip_dag.py
[2022-04-29 01:56:29,809] {processor.py:652} INFO - DAG(s) dict_keys(['example_skip_dag']) retrieved from /home/airflow/.local/lib/python3.7/site-packages/airflow/example_dags/example_skip_dag.py
[2022-04-29 01:57:10,212] {logging_mixin.py:109} INFO - [2022-04-29 01:57:10,211] {manager.py:496} INFO - Created Permission View: can edit on DAG:example_skip_dag
[2022-04-29 01:57:10,244] {logging_mixin.py:109} INFO - [2022-04-29 01:57:10,243] {manager.py:496} INFO - Created Permission View: can read on DAG:example_skip_dag
[2022-04-29 01:57:10,247] {logging_mixin.py:109} INFO - [2022-04-29 01:57:10,246] {dag.py:2398} INFO - Sync 1 DAGs
[2022-04-29 01:57:10,276] {logging_mixin.py:109} INFO - [2022-04-29 01:57:10,275] {dag.py:2417} INFO - Creating ORM DAG for example_skip_dag
[2022-04-29 01:57:10,310] {logging_mixin.py:109} INFO - [2022-04-29 01:57:10,310] {dag.py:2937} INFO - Setting next_dagrun for example_skip_dag to 2022-04-28T01:57:10.308410+00:00
[2022-04-29 01:57:10,354] {processor.py:171} INFO - Processing /home/airflow/.local/lib/python3.7/site-packages/airflow/example_dags/example_skip_dag.py took 40.788 seconds
